Workbook
Name avgunitp: Calculations!$G$4
Name totalsales: Calculations!$A$4
Name transaction: Calculations!$E$4
Name unitssold: Calculations!$C$4

Sheet Cover
B2: Capstone project

Sheet Raw Data
A1: Date | B1: Region | C1: Product | D1: Category | E1: Column1 | F1: Units Sold | G1: Unit Price | H1: Sales Rep | I1: Customer
A2: 45821 | B2: South | C2: LAPTOP A15 | D2: computers | E2: =PROPER(TRIM(D2)) -> Computers | F2: 8 | G2: 2500000 | H2: Peter Obi | I2: bright solutions
A3: 45755 | B3: EAST | C3: tv 43q | D3: ELECTRONICS | E3: =PROPER(TRIM(D3)) -> Electronics | F3: 6 | G3: 350000 | H3: Ifeanyi Okafor | I3: Musa Enterprises
A4: 45686 | B4: North | C4: PHONE X12 | D4: Mobile | E4: =PROPER(TRIM(D4)) -> Mobile | F4: 14 | G4: 180000 | H4: fola balogun | I4: ZAINAB GLOBAL
A5: 17-MAY-2025 | B5: South | C5: MONITOR M24 | D5: PERIPHERALS | E5: =PROPER(TRIM(D5)) -> Peripherals | F5: 18 | G5: 65000 | H5: IFEANYI OKAFOR | I5: Jide Superstores
A6: 28-jan-2025 | B6: WEST | C6: Phone X12 | D6: Mobile | E6: =PROPER(TRIM(D6)) -> Mobile | F6: 5 | G6: 180000 | H6: peter obi | I6: chika mart
A7: 26-May-2025 | B7: east | C7: Phone X12 | D7: mobile | E7: =PROPER(TRIM(D7)) -> Mobile | F7: 19 | G7: 157427 | H7: IFEANYI OKAFOR | I7: Musa Enterprises
A8: 06-MAY-2025 | B8: WEST | C8: tv 43q | D8: Electronics | E8: =PROPER(TRIM(D8)) -> Electronics | F8: 3 | G8: 350000 | H8: AISHA BELLO | I8: Chika Mart
A9: 10-Feb-2025 | B9: west | C9: monitor m24 | D9: peripherals | E9: =PROPER(TRIM(D9)) -> Peripherals | F9: 2 | G9: 65000 | H9: peter obi | I9: Musa Enterprises
A10: 01-FEB-2025 | B10: East | C10: CAMERA C100 | D10: PHOTOGRAPHY | E10: =PROPER(TRIM(D10)) -> Photography | F10: 14 | G10: 175000 | H10: fola balogun | I10: BRIGht SOLUTIONS
A11: 28-Jun-2025 | B11: West | C11: Tablet T8 | D11: mobile | E11: =PROPER(TRIM(D11)) -> Mobile | F11: 4 | G11: 150000 | H11: Peter Obi | I11: Alpha Retailers
A12: 18-Apr-2025 | B12: south | C12: TABLET T8 | D12: Mobile | E12: =PROPER(TRIM(D12)) -> Mobile | F12: 20 | G12: 150000 | H12: fola balogun | I12: MUSA ENTERPRISES
A13: 25-Feb-2025 | B13: North | C13: Speaker S10 | D13: Audio | E13: =PROPER(TRIM(D13)) -> Audio | F13: 6 | G13: 85000 | H13: Aisha Bello | I13: Omega Wholesale
A14: 29-Apr-2025 | B14: WEST | C14: TABLET T8 | D14: Mobile | E14: =PROPER(TRIM(D14)) -> Mobile | F14: 1 | G14: 150000 | H14: AISHA BELLO | I14: kelvin tech
A15: 02-Feb-2025 | B15: east | C15: tv 43q | D15: ELECTRONICS | E15: =PROPER(TRIM(D15)) -> Electronics | F15: 18 | G15: 35000 | H15: Chinedu Nwosu | I15: EMEKA TRADERS
A16: 15-Apr-2025 | B16: SOUTH | C16: Speaker S10 | D16: Audio | E16: =PROPER(TRIM(D16)) -> Audio | F16: 2 | G16: 85000 | H16: ifeanyi okafor | I16: BRIGHT SOLUTIONS
... A21: 26-FEB-2025 | B21: North | C21: Camera C100 | D21: Photography | E21: =PROPER(TRIM(D21)) -> Photography | F21: 5 | G21: 175000 | H21: Chinedu Nwosu | I21: Femi Tech
A22: 45753 | B22: EAST | C22: Laptop A15 | D22: Computers | E22: =PROPER(TRIM(D22)) -> Computers | F22: 20 | G22: 250000 | H22: GRACE AMOS | I22: Musa Enterprises
A23: 24-FEB-2025 | B23: East | C23: camera c100 | D23: Photography | E23: =PROPER(TRIM(D23)) -> Photography | F23: 2 | G23: 175000 | H23: PETER OBI | I23: Emeka Traders
A24: 24-mar-2025 | B24: EAST | C24: Tablet T8 | D24: mobile | E24: =PROPER(TRIM(D24)) -> Mobile | F24: 20 | G24: 150000 | H24: Fola Balogun | I24: Maryam Ltd
A25: 28-May-2025 | B25: north | C25: Tablet T8 | D25: mobile | E25: =PROPER(TRIM(D25)) -> Mobile | F25: 8 | G25: 150000 | H25: ifeanyi okafor | I25: omega wholesale
A26: 12-MAY-2025 | B26: West | C26: Laptop A15 | D26: Computers | E26: =PROPER(TRIM(D26)) -> Computers | F26: 19 | G26: 250000 | H26: Grace Amos | I26: femi tech
A27: 11-MAY-2025 | B27: East | C27: Camera C010 | D27: photography | E27: =PROPER(TRIM(D27)) -> Photography | F27: 12 | G27: 175000 | H27: chinedu nwosu | I27: Omega Wholesale
A28: 16-JAN-2025 | B28: North | C28: SPEAKER S10 | D28: Audio | E28: =PROPER(TRIM(D28)) -> Audio | F28: 11 | G28: 85000 | H28: grace amos | I28: Femi Tech
A29: 10-May-2025 | B29: north | C29: Monitor M24 | D29: PERIPHERALS | E29: =PROPER(TRIM(D29)) -> Peripherals | F29: 17 | G29: 65000 | H29: Chinedu Nwosu | I29: Kelvin Tech
A30: 01-feb-2025 | B30: South | C30: TV 43Q | D30: elecrtonics | E30: =PROPER(TRIM(D30)) -> Elecrtonics | F30: 15 | G30: 350000 | H30: Job Austin | I30: Zainab Global
A31: 06-feb-2025 | B31: west | C31: tv 43q | D31: Electronics | E31: =PROPER(TRIM(D31)) -> Electronics | F31: 8 | G31: 350000 | H31: peter obi | I31: Femi Tech
A32: 17-JUN-2025 | B32: west | C32: tv 43q | D32: Electronics | E32: =PROPER(TRIM(D32)) -> Electronics | F32: 14 | G32: 350000 | H32: Chinedu Nwosu | I32: Tope & Sons
A33: 09-Jan-2025 | B33: East | C33: TABLET T8 | D33: mobile | E33: =PROPER(TRIM(D33)) -> Mobile | F33: 12 | G33: 150000 | H33: fola balogun | I33: alpha retailers
A34: 29-Jun-2025 | B34: North | C34: Camera C100 | D34: PHOTOGRAPHY | E34: =PROPER(TRIM(D34)) -> Photography | F34: 8 | G34: 175000 | H34: Peter Obi | I34: Alpha Retailers
A35: 45735 | B35: South | C35: Tablet T8 | D35: mobile | E35: =PROPER(TRIM(D35)) -> Mobile | F35: 6 | G35: 150000 | H35: Peter Obi | I35: Femi Tech
A36: 06-Feb-2025 | B36: West | C36: laptop a15 | D36: Computers | E36: =PROPER(TRIM(D36)) -> Computers | F36: 20 | G36: 2500000 | H36: Peter Obi | I36: Omega Wholesale
A37: 06-Apr-2025 | B37: South | C37: Monitor M24 | D37: Peripherals | E37: =PROPER(TRIM(D37)) -> Peripherals | F37: 12 | G37: 65000 | H37: peter obi | I37: maryam ltd
A38: 07-Feb-2025 | B38: South | C38: Monitor M24 | D38: Peripherals | E38: =PROPER(TRIM(D38)) -> Peripherals | F38: 4 | G38: 73740 | H38: Mary John | I38: TOPE & SONS
A39: 07-mar-2025 | B39: east | C39: CAMERA C100 | D39: PHOTOGRAPHY | E39: =PROPER(TRIM(D39)) -> Photography | F39: 18 | G39: 175000 | H39: GRACE AMOS | I39: BRIGHT SOLUTIONS
A40: 07-May-2025 | B40: North | C40: PHONE X12 | D40: Mobile. | E40: =PROPER(TRIM(D40)) -> Mobile. | F40: 10 | G40: 180000 | H40: MARY JOHN | I40: Chika Mart
A41: 30-Jun-2025 | B41: EAST | C41: unknown | D41: PERIPHERALS | E41: =PROPER(TRIM(D41)) -> Peripherals | F41: 10 | G41: 65000 | H41: Aba Joel | I41: Musa Enterprises
A42: 25-Feb-2025 | B42: NORTH | C42: TABLET T8 | D42: Mobile | E42: =PROPER(TRIM(D42)) -> Mobile | F42: 3 | G42: 150000 | H42: mary john | I42: TOPE & SONS
A43: 13-Jan-2025 | B43: SOUTH | C43: PHONE X12 | D43: Mobile | E43: =PROPER(TRIM(D43)) -> Mobile | F43: 8 | G43: 180000 | H43: AISHA BELLO | I43: Omega Wholesale
A44: 15-JUN-2025 | B44: south | C44: LAPTOP A15 | D44: Computers | E44: =PROPER(TRIM(D44)) -> Computers | F44: 3 | G44: 250000 | H44: Mary John | I44: Chika Mart
...

Sheet Data Cleaning
A1: Date | B1: Proper Date | C1: Region | D1: Product | E1: Units Sold | F1: Unit Price | G1: Sale Rep | H1: Customers | I1: Total sales
A2: =TEXT(TRIM(UPPER(CLEAN('Raw Data'!A2))),"dd/mm/yyy") -> 13/06/2025 | B2: =DATE(RIGHT(Table2[[#This Row],[Date]],4), MID(Table2[[#This Row],[Date]],4,2), LEFT(Table2[[#This Row],[Date]],2)) -> 45821 | C2: =PROPER(TRIM('Raw Data'!B2)) -> South | D2: =UPPER(TRIM(CLEAN(('Raw Data'!C2)))) -> LAPTOP A15 | E2: 8 | F2: 2500000 | G2: =PROPER(TRIM('Raw Data'!H2)) -> Peter Obi | H2: =PROPER(TRIM('Raw Data'!I2)) -> Bright Solutions | I2: =E2*F2 -> 20000000
A3: =TEXT(TRIM(UPPER(CLEAN('Raw Data'!A3))),"dd/mm/yyy") -> 08/04/2025 | B3: =DATE(RIGHT(Table2[[#This Row],[Date]],4), MID(Table2[[#This Row],[Date]],4,2), LEFT(Table2[[#This Row],[Date]],2)) -> 45755 | C3: =PROPER(TRIM('Raw Data'!B3)) -> East | D3: =UPPER(TRIM(CLEAN(('Raw Data'!C3)))) -> TV 43Q | E3: 6 | F3: 350000 | G3: =PROPER(TRIM('Raw Data'!H3)) -> Ifeanyi Okafor | H3: =PROPER(TRIM('Raw Data'!I3)) -> Musa Enterprises | I3: =E3*F3 -> 2100000
A4: =TEXT(TRIM(UPPER(CLEAN('Raw Data'!A4))),"dd/mm/yyy") -> 29/01/2025 | B4: =DATE(RIGHT(Table2[[#This Row],[Date]],4), MID(Table2[[#This Row],[Date]],4,2), LEFT(Table2[[#This Row],[Date]],2)) -> 45686 | C4: =PROPER(TRIM('Raw Data'!B4)) -> North | D4: =UPPER(TRIM(CLEAN(('Raw Data'!C4)))) -> PHONE X12 | E4: 14 | F4: 180000 | G4: =PROPER(TRIM('Raw Data'!H4)) -> Fola Balogun | H4: =PROPER(TRIM('Raw Data'!I4)) -> Zainab Global | I4: =E4*F4 -> 2520000
A5: =TEXT(TRIM(UPPER(CLEAN('Raw Data'!A5))),"dd/mm/yyy") -> 17/05/2025 | B5: =DATE(RIGHT(Table2[[#This Row],[Date]],4), MID(Table2[[#This Row],[Date]],4,2), LEFT(Table2[[#This Row],[Date]],2)) -> 45794 | C5: =PROPER(TRIM('Raw Data'!B5)) -> South | D5: =UPPER(TRIM(CLEAN(('Raw Data'!C5)))) -> MONITOR M24 | E5: 18 | F5: 65000 | G5: =PROPER(TRIM('Raw Data'!H5)) -> Ifeanyi Okafor | H5: =PROPER(TRIM('Raw Data'!I5)) -> Jide Superstores | I5: =E5*F5 -> 1170000
A6: =TEXT(TRIM(UPPER(CLEAN('Raw Data'!A6))),"dd/mm/yyy") -> 28/01/2025 | B6: =DATE(RIGHT(Table2[[#This Row],[Date]],4), MID(Table2[[#This Row],[Date]],4,2), LEFT(Table2[[#This Row],[Date]],2)) -> 45685 | C6: =PROPER(TRIM('Raw Data'!B6)) -> West | D6: =UPPER(TRIM(CLEAN(('Raw Data'!C6)))) -> PHONE X12 | E6: 5 | F6: 180000 | G6: =PROPER(TRIM('Raw Data'!H6)) -> Peter Obi | H6: =PROPER(TRIM('Raw Data'!I6)) -> Chika Mart | I6: =E6*F6 -> 900000
A7: =TEXT(TRIM(UPPER(CLEAN('Raw Data'!A7))),"dd/mm/yyy") -> 26/05/2025 | B7: =DATE(RIGHT(Table2[[#This Row],[Date]],4), MID(Table2[[#This Row],[Date]],4,2), LEFT(Table2[[#This Row],[Date]],2)) -> 45803 | C7: =PROPER(TRIM('Raw Data'!B7)) -> East | D7: =UPPER(TRIM(CLEAN(('Raw Data'!C7)))) -> PHONE X12 | E7: 19 | F7: 157427 | G7: =PROPER(TRIM('Raw Data'!H7)) -> Ifeanyi Okafor | H7: =PROPER(TRIM('Raw Data'!I7)) -> Musa Enterprises | I7: =E7*F7 -> 2991113
A8: =TEXT(TRIM(UPPER(CLEAN('Raw Data'!A8))),"dd/mm/yyy") -> 06/05/2025 | B8: =DATE(RIGHT(Table2[[#This Row],[Date]],4), MID(Table2[[#This Row],[Date]],4,2), LEFT(Table2[[#This Row],[Date]],2)) -> 45783 | C8: =PROPER(TRIM('Raw Data'!B8)) -> West | D8: =UPPER(TRIM(CLEAN(('Raw Data'!C8)))) -> TV 43Q | E8: 3 | F8: 350000 | G8: =PROPER(TRIM('Raw Data'!H8)) -> Aisha Bello | H8: =PROPER(TRIM('Raw Data'!I8)) -> Chika Mart | I8: =E8*F8 -> 1050000
A9: =TEXT(TRIM(UPPER(CLEAN('Raw Data'!A9))),"dd/mm/yyy") -> 10/02/2025 | B9: =DATE(RIGHT(Table2[[#This Row],[Date]],4), MID(Table2[[#This Row],[Date]],4,2), LEFT(Table2[[#This Row],[Date]],2)) -> 45698 | C9: =PROPER(TRIM('Raw Data'!B9)) -> West | D9: =UPPER(TRIM(CLEAN(('Raw Data'!C9)))) -> MONITOR M24 | E9: 2 | F9: 65000 | G9: =PROPER(TRIM('Raw Data'!H9)) -> Peter Obi | H9: =PROPER(TRIM('Raw Data'!I9)) -> Musa Enterprises | I9: =E9*F9 -> 130000
A10: =TEXT(TRIM(UPPER(CLEAN('Raw Data'!A10))),"dd/mm/yyy") -> 01/02/2025 | B10: =DATE(RIGHT(Table2[[#This Row],[Date]],4), MID(Table2[[#This Row],[Date]],4,2), LEFT(Table2[[#This Row],[Date]],2)) -> 45689 | C10: =PROPER(TRIM('Raw Data'!B10)) -> East | D10: =UPPER(TRIM(CLEAN(('Raw Data'!C10)))) -> CAMERA C100 | E10: 14 | F10: 175000 | G10: =PROPER(TRIM('Raw Data'!H10)) -> Fola Balogun | H10: =PROPER(TRIM('Raw Data'!I10)) -> Bright Solutions | I10: =E10*F10 -> 2450000
A11: =TEXT(TRIM(UPPER(CLEAN('Raw Data'!A11))),"dd/mm/yyy") -> 28/06/2025 | B11: =DATE(RIGHT(Table2[[#This Row],[Date]],4), MID(Table2[[#This Row],[Date]],4,2), LEFT(Table2[[#This Row],[Date]],2)) -> 45836 | C11: =PROPER(TRIM('Raw Data'!B11)) -> West | D11: =UPPER(TRIM(CLEAN(('Raw Data'!C11)))) -> TABLET T8 | E11: 4 | F11: 150000 | G11: =PROPER(TRIM('Raw Data'!H11)) -> Peter Obi | H11: =PROPER(TRIM('Raw Data'!I11)) -> Alpha Retailers | I11: =E11*F11 -> 600000
A12: =TEXT(TRIM(UPPER(CLEAN('Raw Data'!A12))),"dd/mm/yyy") -> 18/04/2025 | B12: =DATE(RIGHT(Table2[[#This Row],[Date]],4), MID(Table2[[#This Row],[Date]],4,2), LEFT(Table2[[#This Row],[Date]],2)) -> 45765 | C12: =PROPER(TRIM('Raw Data'!B12)) -> South | D12: =UPPER(TRIM(CLEAN(('Raw Data'!C12)))) -> TABLET T8 | E12: 20 | F12: 150000 | G12: =PROPER(TRIM('Raw Data'!H12)) -> Fola Balogun | H12: =PROPER(TRIM('Raw Data'!I12)) -> Musa Enterprises | I12: =E12*F12 -> 3000000
A13: =TEXT(TRIM(UPPER(CLEAN('Raw Data'!A13))),"dd/mm/yyy") -> 25/02/2025 | B13: =DATE(RIGHT(Table2[[#This Row],[Date]],4), MID(Table2[[#This Row],[Date]],4,2), LEFT(Table2[[#This Row],[Date]],2)) -> 45713 | C13: =PROPER(TRIM('Raw Data'!B13)) -> North | D13: =UPPER(TRIM(CLEAN(('Raw Data'!C13)))) -> SPEAKER S10 | E13: 6 | F13: 85000 | G13: =PROPER(TRIM('Raw Data'!H13)) -> Aisha Bello | H13: =PROPER(TRIM('Raw Data'!I13)) -> Omega Wholesale | I13: =E13*F13 -> 510000
... A101: =TEXT(TRIM(UPPER(CLEAN('Raw Data'!A101))),"dd/mm/yyy") -> 13/05/2025 | B101: =DATE(RIGHT(Table2[[#This Row],[Date]],4), MID(Table2[[#This Row],[Date]],4,2), LEFT(Table2[[#This Row],[Date]],2)) -> 45790 | C101: =PROPER(TRIM('Raw Data'!B101)) -> West | D101: =UPPER(TRIM(CLEAN(('Raw Data'!C101)))) -> TABLET T8 | E101: 18 | F101: 150000 | G101: =PROPER(TRIM('Raw Data'!H101)) -> Grace Amos | H101: =PROPER(TRIM('Raw Data'!I101)) -> Alpha Retailers | I101: =E101*F101 -> 2700000

Sheet Calculations
A1: Core KPIs
A3: Sum of Total Revenue | C3: Sum of Units Sold | E3: Number of Transactions | G3: Average of Unit Price
A4: 302680445 | C4: 1141 | E4: 100 | G4: 248238.47
A6: REGIONAL PERFORMANCE
A7: Total Sales by Region | D7: Units Sold by Region
A8: Row Labels | B8: Sum of Total sales | C8: Sum of Total sales2 | D8: Row Labels | E8: Sum of Units Sold | F8: Sum of Units Sold2
A9: West | B9: 115542487 | C9: 115542487 | D9: East | E9: 430 | F9: 430
A10: East | B10: 79518498 | C10: 79518498 | D10: North | E10: 196 | F10: 196
A11: South | B11: 68129460 | C11: 68129460 | D11: South | E11: 292 | F11: 292
A12: North | B12: 39490000 | C12: 39490000 | D12: West | E12: 223 | F12: 223
A18: PRODUCT PERFORMANCE
A19: Total Sales by Product | D19: Units Sold by Product
A20: Row Labels | B20: Sum of Total sales | D20: Row Labels | E20: Sum of Units Sold
A21: CAMER AC100 | B21: 1750000 | D21: LAPTOP A15 | E21: 191
A22: CAMERA C010 | B22: 2100000 | D22: MONITOR M24 | E22: 166
A23: CAMERA C100 | B23: 21700000 | D23: TABLET T8 | E23: 226
A24: LAPTOP A15 | B24: 134375000 | D24: TV 43Q | E24: 215
A25: MONITOR M24 | B25: 21230201
A26: PHONE X12 | B26: 14331113
A27: SPEAKER S10 | B27: 8954631
A28: TABLET T8 | B28: 33900000
A29: TV 43Q | B29: 63689500
A30: UNKNOWN | B30: 650000
A37: SALES TREND (WHEN) | D37: CUSTOMER INSIGHTS (WHO BUYS)
A38: Monthly Sales Trend | D38: Top Customers by Sales | G38: Repeat Customers
A39: Row Labels | B39: Sum of Total sales | D39: Row Labels | E39: Sum of Total sales | G39: Row Labels | H39: Count of Date
A40: Jan | B40: 57202856 | D40: Omega Wholesale | E40: 89559500 | G40: Femi Tech | H40: 13
A41: Feb | B41: 124284591 | D41: Bright Solutions | E41: 31715000 | G41: Musa Enterprises | H41: 11
A42: Mar | B42: 18545000 | D42: Femi Tech | E42: 31117487 | G42: Omega Wholesale | H42: 9
A43: Apr | B43: 24620000 | D43: Musa Enterprises | E43: 27191113 | G43: Bright Solutions | H43: 8
A44: May | B44: 31856113 | D44: Jide Superstores | E44: 23270000 | G44: Chika Mart | H44: 8
A45: Jun | B45: 46171885 | G45: Kelvin Tech | H45: 7
G46: Emeka Traders | H46: 7
A47: SALES REP PERFORMANCE (WHO) | G47: Jide Superstores | H47: 6
A48: Sales by Sales Rep | G48: Alpha Retailers | H48: 6
A49: Row Labels | B49: Sum of Total sales | G49: Maryam Ltd | H49: 6
A50: Peter Obi | B50: 87790000 | G50: Tola Ventures | H50: 5
A51: Fola Balogun | B51: 58707487 | G51: Zainab Global | H51: 4
A52: Grace Amos | B52: 39910000 | G52: Tope & Sons | H52: 4
A53: Chinedu Nwosu | B53: 36226885 | G53: Adewale Stores | H53: 3
...

Sheet Dashbord

Sheet Sheet1
